Workbook

Sheet Hoja2
A1: Comuna | B1: Poblacion | C1: Hombres | D1: Mujeres
A2: 1 | B2: 60799 | C2: 0.468 | D2: 0.532
A3: 2 | B3: 118956 | C3: 0.462 | D3: 0.538
A4: 3 | B4: 33652 | C4: 0.488 | D4: 0.512
A5: 4 | B5: 56189 | C5: 0.462 | D5: 0.538
A6: 5 | B6: 114776 | C6: 0.443 | D6: 0.557
A7: 6 | B7: 154154 | C7: 0.461 | D7: 0.539
A8: 7 | B8: 71049 | C8: 0.459 | D8: 0.541
A9: 8 | B9: 100226 | C9: 0.453 | D9: 0.547
A10: 9 | B10: 37165 | C10: 0.476 | D10: 0.524
A11: 10 | B11: 104729 | C11: 0.449 | D11: 0.551
A12: 11 | B12: 111204 | C12: 0.456 | D12: 0.544
A13: 12 | B13: 69956 | C13: 0.46 | D13: 0.54
... A23: 22 | B23: 26104 | C23: 0.498 | D23: 0.502

Sheet Resumen
A1: Comuna | B1: Población | C1: Hombres | D1: Mujeres | E1: Niños (0 - 14) | F1: Jóvenes (15 - 24) | G1: Adultos (25 - 59) | H1: Mayores (60 y +)
A2: {=_xlfn.SEQUENCE(22)} -> 1 | B2: =Poblacion!$D6 -> 60799 | C2: 0.468 | D2: 0.532 | E2: 0.256 | F2: 0.199 | G2: 0.46 | H2: 0.084
A3: 2 | B3: =Poblacion!H6 -> 118956 | C3: 0.462 | D3: 0.538 | E3: 0.26 | F3: 0.199 | G3: 0.448 | H3: 0.093
A4: 3 | B4: =Poblacion!L6 -> 33652 | C4: 0.488 | D4: 0.512 | E4: 0.211 | F4: 0.171 | G4: 0.473 | H4: 0.144
A5: 4 | B5: =Poblacion!P6 -> 56189 | C5: 0.462 | D5: 0.538 | E5: 0.208 | F5: 0.185 | G5: 0.481 | H5: 0.125
A6: 5 | B6: =Poblacion!D17 -> 114776 | C6: 0.443 | D6: 0.557 | E6: 0.169 | F6: 0.173 | G6: 0.535 | H6: 0.124
A7: 6 | B7: =Poblacion!H17 -> 154154 | C7: 0.461 | D7: 0.539 | E7: 0.222 | F7: 0.198 | G7: 0.487 | H7: 0.092
A8: 7 | B8: =Poblacion!L17 -> 71049 | C8: 0.459 | D8: 0.541 | E8: 0.24 | F8: 0.195 | G8: 0.462 | H8: 0.103
A9: 8 | B9: =Poblacion!P17 -> 100226 | C9: 0.453 | D9: 0.547 | E9: 0.19 | F9: 0.182 | G9: 0.497 | H9: 0.132
A10: 9 | B10: =Poblacion!D28 -> 37165 | C10: 0.476 | D10: 0.524 | E10: 0.212 | F10: 0.176 | G10: 0.466 | H10: 0.147
A11: 10 | B11: =Poblacion!H28 -> 104729 | C11: 0.449 | D11: 0.551 | E11: 0.205 | F11: 0.192 | G11: 0.475 | H11: 0.128
A12: 11 | B12: =Poblacion!L28 -> 111204 | C12: 0.456 | D12: 0.544 | E12: 0.207 | F12: 0.187 | G12: 0.487 | H12: 0.119
A13: 12 | B13: =Poblacion!P28 -> 69956 | C13: 0.46 | D13: 0.54 | E13: 0.221 | F13: 0.193 | G13: 0.481 | H13: 0.105
A14: 13 | B14: =Poblacion!D39 -> 145047 | C14: 0.461 | D14: 0.539 | E14: 0.274 | F14: 0.201 | G14: 0.442 | H14: 0.082
A15: 14 | B15: =Poblacion!H39 -> 157639 | C15: 0.46 | D15: 0.54 | E15: 0.292 | F15: 0.207 | G15: 0.431 | H15: 0.071
A16: 15 | B16: =Poblacion!L39 -> 126766 | C16: 0.453 | D16: 0.547 | E16: 0.306 | F16: 0.208 | G16: 0.421 | H16: 0.066
A17: 16 | B17: =Poblacion!P39 -> 99041 | C17: 0.46 | D17: 0.54 | E17: 0.247 | F17: 0.2 | G17: 0.458 | H17: 0.094
A18: 17 | B18: =Poblacion!D50 -> 168998 | C18: 0.431 | D18: 0.569 | E18: 0.198 | F18: 0.177 | G18: 0.483 | H18: 0.142
A19: 18 | B19: =Poblacion!H50 -> 115529 | C19: 0.465 | D19: 0.535 | E19: 0.271 | F19: 0.205 | G19: 0.451 | H19: 0.073
A20: 19 | B20: =Poblacion!L50 -> 111310 | C20: 0.466 | D20: 0.534 | E20: 0.218 | F20: 0.192 | G20: 0.473 | H20: 0.117
A21: 20 | B21: =Poblacion!P50 -> 58827 | C21: 0.47 | D21: 0.53 | E21: 0.275 | F21: 0.209 | G21: 0.437 | H21: 0.079
A22: 21 | B22: =Poblacion!D61 -> 132544 | C22: 0.458 | D22: 0.542 | E22: 0.311 | F22: 0.211 | G22: 0.431 | H22: 0.046
A23: 22 | B23: =Poblacion!H61 -> 26104 | C23: 0.498 | D23: 0.502 | E23: 0.249 | F23: 0.201 | G23: 0.482 | H23: 0.069

Sheet Poblacion
B2: Género y Edad de SISBEN III 2020 Población de Datos Generales
B4: Comuna 1 | F4: Comuna 2 | J4: Comuna 3 | N4: Comuna 4
B5: Variable | C5: Unidad | D5: Valor | F5: Variable | G5: Unidad | H5: Valor | J5: Variable | K5: Unidad | L5: Valor | N5: Variable | O5: Unidad | P5: Valor
B6: Población | C6: Personas | D6: 60799 | F6: Población | G6: Personas | H6: 118956 | J6: Población | K6: Personas | L6: 33652 | N6: Población | O6: Personas | P6: 56189
B7: Hombre | C7: Porcentaje | D7: 46.8 | F7: Hombre | G7: Porcentaje | H7: 46.2 | J7: Hombre | K7: Porcentaje | L7: 48.8 | N7: Hombre | O7: Porcentaje | P7: 46.2
B8: Mujer | C8: Porcentaje | D8: 53.2 | F8: Mujer | G8: Porcentaje | H8: 53.8 | J8: Mujer | K8: Porcentaje | L8: 51.2 | N8: Mujer | O8: Porcentaje | P8: 53.8
B9: Grupos de edad (años) | F9: Grupos de edad (años) | J9: Grupos de edad (años) | N9: Grupos de edad (años)
B10: Niños (0 - 14) | C10: Porcentaje | D10: 25.6 | F10: Niños (0 - 14) | G10: Porcentaje | H10: 26 | J10: Niños (0 - 14) | K10: Porcentaje | L10: 21.1 | N10: Niños (0 - 14) | O10: Porcentaje | P10: 20.8
B11: Jóvenes (15 - 24) | C11: Porcentaje | D11: 19.9 | F11: Jóvenes (15 - 24) | G11: Porcentaje | H11: 19.9 | J11: Jóvenes (15 - 24) | K11: Porcentaje | L11: 17.1 | N11: Jóvenes (15 - 24) | O11: Porcentaje | P11: 18.5
B12: Adultos (25 - 59) | C12: Porcentaje | D12: 46 | F12: Adultos (25 - 59) | G12: Porcentaje | H12: 44.8 | J12: Adultos (25 - 59) | K12: Porcentaje | L12: 47.3 | N12: Adultos (25 - 59) | O12: Porcentaje | P12: 48.1
B13: Mayores (60 y +) | C13: Porcentaje | D13: 8.4 | F13: Mayores (60 y +) | G13: Porcentaje | H13: 9.3 | J13: Mayores (60 y +) | K13: Porcentaje | L13: 14.4 | N13: Mayores (60 y +) | O13: Porcentaje | P13: 12.5
B15: Comuna 5 | F15: Comuna 6 | J15: Comuna 7 | N15: Comuna 8
B16: Variable | C16: Unidad | D16: Valor | F16: Variable | G16: Unidad | H16: Valor | J16: Variable | K16: Unidad | L16: Valor | N16: Variable | O16: Unidad | P16: Valor
B17: Población | C17: Personas | D17: 114776 | F17: Población | G17: Personas | H17: 154154 | J17: Población | K17: Personas | L17: 71049 | N17: Población | O17: Personas | P17: 100226
B18: Hombre | C18: Porcentaje | D18: 44.3 | F18: Hombre | G18: Porcentaje | H18: 46.1 | J18: Hombre | K18: Porcentaje | L18: 45.9 | N18: Hombre | O18: Porcentaje | P18: 45.3
B19: Mujer | C19: Porcentaje | D19: 55.7 | F19: Mujer | G19: Porcentaje | H19: 53.9 | J19: Mujer | K19: Porcentaje | L19: 54.1 | N19: Mujer | O19: Porcentaje | P19: 54.7
B20: Grupos de edad (años) | F20: Grupos de edad (años) | J20: Grupos de edad (años) | N20: Grupos de edad (años)
B21: Niños (0 - 14) | C21: Porcentaje | D21: 16.9 | F21: Niños (0 - 14) | G21: Porcentaje | H21: 22.2 | J21: Niños (0 - 14) | K21: Porcentaje | L21: 24 | N21: Niños (0 - 14) | O21: Porcentaje | P21: 19
B22: Jóvenes (15 - 24) | C22: Porcentaje | D22: 17.3 | F22: Jóvenes (15 - 24) | G22: Porcentaje | H22: 19.8 | J22: Jóvenes (15 - 24) | K22: Porcentaje | L22: 19.5 | N22: Jóvenes (15 - 24) | O22: Porcentaje | P22: 18.2
B23: Adultos (25 - 59) | C23: Porcentaje | D23: 53.5 | F23: Adultos (25 - 59) | G23: Porcentaje | H23: 48.7 | J23: Adultos (25 - 59) | K23: Porcentaje | L23: 46.2 | N23: Adultos (25 - 59) | O23: Porcentaje | P23: 49.7
B24: Mayores (60 y +) | C24: Porcentaje | D24: 12.4 | F24: Mayores (60 y +) | G24: Porcentaje | H24: 9.2 | J24: Mayores (60 y +) | K24: Porcentaje | L24: 10.3 | N24: Mayores (60 y +) | O24: Porcentaje | P24: 13.2
B26: Comuna 9 | F26: Comuna 10 | J26: Comuna 11 | N26: Comuna 12
B27: Variable | C27: Unidad | D27: Valor | F27: Variable | G27: Unidad | H27: Valor | J27: Variable | K27: Unidad | L27: Valor | N27: Variable | O27: Unidad | P27: Valor
B28: Población | C28: Personas | D28: 37165 | F28: Población | G28: Personas | H28: 104729 | J28: Población | K28: Personas | L28: 111204 | N28: Población | O28: Personas | P28: 69956
B29: Hombre | C29: Porcentaje | D29: 47.6 | F29: Hombre | G29: Porcentaje | H29: 44.9 | J29: Hombre | K29: Porcentaje | L29: 45.6 | N29: Hombre | O29: Porcentaje | P29: 46
B30: Mujer | C30: Porcentaje | D30: 52.4 | F30: Mujer | G30: Porcentaje | H30: 55.1 | J30: Mujer | K30: Porcentaje | L30: 54.4 | N30: Mujer | O30: Porcentaje | P30: 54
B31: Grupos de edad (años) | F31: Grupos de edad (años) | J31: Grupos de edad (años) | N31: Grupos de edad (años)
B32: Niños (0 - 14) | C32: Porcentaje | D32: 21.2 | F32: Niños (0 - 14) | G32: Porcentaje | H32: 20.5 | J32: Niños (0 - 14) | K32: Porcentaje | L32: 20.7 | N32: Niños (0 - 14) | O32: Porcentaje | P32: 22.1
B33: Jóvenes (15 - 24) | C33: Porcentaje | D33: 17.6 | F33: Jóvenes (15 - 24) | G33: Porcentaje | H33: 19.2 | J33: Jóvenes (15 - 24) | K33: Porcentaje | L33: 18.7 | N33: Jóvenes (15 - 24) | O33: Porcentaje | P33: 19.3
B34: Adultos (25 - 59) | C34: Porcentaje | D34: 46.6 | F34: Adultos (25 - 59) | G34: Porcentaje | H34: 47.5 | J34: Adultos (25 - 59) | K34: Porcentaje | L34: 48.7 | N34: Adultos (25 - 59) | O34: Porcentaje | P34: 48.1
B35: Mayores (60 y +) | C35: Porcentaje | D35: 14.7 | F35: Mayores (60 y +) | G35: Porcentaje | H35: 12.8 | J35: Mayores (60 y +) | K35: Porcentaje | L35: 11.9 | N35: Mayores (60 y +) | O35: Porcentaje | P35: 10.5
B37: Comuna 13 | F37: Comuna 14 | J37: Comuna 15 | N37: Comuna 16
B38: Variable | C38: Unidad | D38: Valor | F38: Variable | G38: Unidad | H38: Valor | J38: Variable | K38: Unidad | L38: Valor | N38: Variable | O38: Unidad | P38: Valor
B39: Población | C39: Personas | D39: 145047 | F39: Población | G39: Personas | H39: 157639 | J39: Población | K39: Personas | L39: 126766 | N39: Población | O39: Personas | P39: 99041
B40: Hombre | C40: Porcentaje | D40: 46.1 | F40: Hombre | G40: Porcentaje | H40: 46 | J40: Hombre | K40: Porcentaje | L40: 45.3 | N40: Hombre | O40: Porcentaje | P40: 46
B41: Mujer | C41: Porcentaje | D41: 53.9 | F41: Mujer | G41: Porcentaje | H41: 54 | J41: Mujer | K41: Porcentaje | L41: 54.7 | N41: Mujer | O41: Porcentaje | P41: 54
B42: Grupos de edad (años) | F42: Grupos de edad (años) | J42: Grupos de edad (años) | N42: Grupos de edad (años)
B43: Niños (0 - 14) | C43: Porcentaje | D43: 27.4 | F43: Niños (0 - 14) | G43: Porcentaje | H43: 29.2 | J43: Niños (0 - 14) | K43: Porcentaje | L43: 30.6 | N43: Niños (0 - 14) | O43: Porcentaje | P43: 24.7
B44: Jóvenes (15 - 24) | C44: Porcentaje | D44: 20.1 | F44: Jóvenes (15 - 24) | G44: Porcentaje | H44: 20.7 | J44: Jóvenes (15 - 24) | K44: Porcentaje | L44: 20.8 | N44: Jóvenes (15 - 24) | O44: Porcentaje | P44: 20
B45: Adultos (25 - 59) | C45: Porcentaje | D45: 44.2 | F45: Adultos (25 - 59) | G45: Porcentaje | H45: 43.1 | J45: Adultos (25 - 59) | K45: Porcentaje | L45: 42.1 | N45: Adultos (25 - 59) | O45: Porcentaje | P45: 45.8
...
